{"trial_id": "0000", "hyperparameters": {"space": [{"class_name": "Int", "config": {"name": "units", "default": null, "conditions": [], "min_value": 32, "max_value": 512, "step": 32, "sampling": "linear"}}, {"class_name": "Int", "config": {"name": "num_layers", "default": null, "conditions": [], "min_value": 1, "max_value": 5, "step": 1, "sampling": "linear"}}, {"class_name": "Choice", "config": {"name": "lr", "default": "0.01", "conditions": [], "values": ["0.01", "0.001", "0.0001"], "ordered": false}}, {"class_name": "Int", "config": {"name": "units_1", "default": null, "conditions": [], "min_value": 32, "max_value": 512, "step": 32, "sampling": "linear"}}, {"class_name": "Choice", "config": {"name": "activation_1", "default": "relu", "conditions": [], "values": ["relu", "sigmoid", "tanh"], "ordered": false}}, {"class_name": "Int", "config": {"name": "units_2", "default": null, "conditions": [], "min_value": 32, "max_value": 512, "step": 32, "sampling": "linear"}}, {"class_name": "Choice", "config": {"name": "activation_2", "default": "relu", "conditions": [], "values": ["relu", "sigmoid", "tanh"], "ordered": false}}, {"class_name": "Int", "config": {"name": "units_3", "default": null, "conditions": [], "min_value": 32, "max_value": 512, "step": 32, "sampling": "linear"}}, {"class_name": "Choice", "config": {"name": "activation_3", "default": "relu", "conditions": [], "values": ["relu", "sigmoid", "tanh"], "ordered": false}}], "values": {"units": 192, "num_layers": 4, "lr": "0.01", "tuner/epochs": 2, "tuner/initial_epoch": 0, "tuner/bracket": 3, "tuner/round": 0, "units_1": 32, "activation_1": "relu", "units_2": 32, "activation_2": "relu", "units_3": 32, "activation_3": "relu"}}, "metrics": {"metrics": {}}, "score": null, "best_step": 0, "status": "FAILED", "message": "Traceback (most recent call last):\n  File \"c:\\Users\\David\\anaconda3\\envs\\dev\\lib\\site-packages\\keras_tuner\\src\\engine\\base_tuner.py\", line 274, in _try_run_and_update_trial\n    self._run_and_update_trial(trial, *fit_args, **fit_kwargs)\n  File \"c:\\Users\\David\\anaconda3\\envs\\dev\\lib\\site-packages\\keras_tuner\\src\\engine\\base_tuner.py\", line 239, in _run_and_update_trial\n    results = self.run_trial(trial, *fit_args, **fit_kwargs)\n  File \"c:\\Users\\David\\anaconda3\\envs\\dev\\lib\\site-packages\\keras_tuner\\src\\tuners\\hyperband.py\", line 427, in run_trial\n    return super().run_trial(trial, *fit_args, **fit_kwargs)\n  File \"c:\\Users\\David\\anaconda3\\envs\\dev\\lib\\site-packages\\keras_tuner\\src\\engine\\tuner.py\", line 314, in run_trial\n    obj_value = self._build_and_fit_model(trial, *args, **copied_kwargs)\n  File \"c:\\Users\\David\\anaconda3\\envs\\dev\\lib\\site-packages\\keras_tuner\\src\\engine\\tuner.py\", line 233, in _build_and_fit_model\n    results = self.hypermodel.fit(hp, model, *args, **kwargs)\n  File \"c:\\Users\\David\\anaconda3\\envs\\dev\\lib\\site-packages\\keras_tuner\\src\\engine\\hypermodel.py\", line 149, in fit\n    return model.fit(*args, **kwargs)\n  File \"c:\\Users\\David\\anaconda3\\envs\\dev\\lib\\site-packages\\keras\\src\\utils\\traceback_utils.py\", line 122, in error_handler\n    raise e.with_traceback(filtered_tb) from None\n  File \"c:\\Users\\David\\anaconda3\\envs\\dev\\lib\\site-packages\\keras\\src\\backend\\tensorflow\\trainer.py\", line 117, in one_step_on_iterator\n    outputs = self.distribute_strategy.run(\nSystemError: \\objects\\listobject.c:336: bad argument to internal function\n"}